2019-01-19 14:18:45.348 [error] <0.60.0> Supervisor {<0.60.0>,user_sup} had child at module user_sup at <0.61.0> exit with reason einval in context child_terminated
2019-01-19 14:18:45.349 [error] <0.60.0> gen_server <0.60.0> terminated with reason: einval
2019-01-19 14:18:45.353 [error] <0.60.0> CRASH REPORT Process <0.60.0> with 0 neighbours exited with reason: einval in gen_server:handle_common_reply/8 line 751
2019-01-19 14:18:45.353 [error] <0.48.0> Supervisor kernel_sup had child user started with user_sup:start() at <0.60.0> exit with reason einval in context child_terminated
2019-01-19 14:18:45.416 [error] <0.172.0> gen_event 'Elixir.Logger.Backends.Console' installed in 'Elixir.Logger' terminated with reason: #{'__exception__' => true,'__struct__' => 'Elixir.RuntimeError',message => <<"no device registered with the name :user">>} in 'Elixir.Logger.Backends.Console':async_io/2 line 160
2019-01-19 14:18:45.520 [error] <0.175.0> gen_server <0.175.0> terminated with reason: {'EXIT',{#{'__exception__' => true,'__struct__' => 'Elixir.RuntimeError',message => <<"no device registered with the name :user">>},[{'Elixir.Logger.Backends.Console',async_io,2,[{file,"lib/logger/backends/console.ex"},{line,160}]},{'Elixir.Logger.Backends.Console',log_event,5,[{file,"lib/logger/backends/console.ex"},{line,145}]},{'Elixir.Logger.Backends.Console',handle_event,2,[{file,"lib/logger/backends/console.ex"},{line,49}]},{gen_event,server_update,4,[{file,"gen_event.erl"},{line,577}]},...]}}
2019-01-19 14:18:45.520 [error] <0.58.0> Supervisor standard_error_sup had child at module standard_error at <0.59.0> exit with reason einval in context child_terminated
2019-01-19 14:18:45.520 [error] <0.58.0> gen_server standard_error_sup terminated with reason: einval
2019-01-19 14:18:45.520 [error] <0.58.0> CRASH REPORT Process standard_error_sup with 0 neighbours exited with reason: einval in gen_server:handle_common_reply/8 line 751
2019-01-19 14:18:45.521 [error] <0.175.0> CRASH REPORT Process <0.175.0> with 0 neighbours exited with reason: {'EXIT',{#{'__exception__' => true,'__struct__' => 'Elixir.RuntimeError',message => <<"no device registered with the name :user">>},[{'Elixir.Logger.Backends.Console',async_io,2,[{file,"lib/logger/backends/console.ex"},{line,160}]},{'Elixir.Logger.Backends.Console',log_event,5,[{file,"lib/logger/backends/console.ex"},{line,145}]},{'Elixir.Logger.Backends.Console',handle_event,2,[{file,"lib/logger/backends/console.ex"},{line,49}]},{gen_event,server_update,4,[{file,"gen_event.erl"},{line,577}]},...]}} in gen_server:handle_common_reply/8 line 751
2019-01-19 14:18:45.522 [error] <0.48.0> Supervisor kernel_sup had child standard_error started with standard_error:start_link() at <0.58.0> exit with reason einval in context child_terminated
2019-01-19 14:18:45.523 [error] <0.174.0> Supervisor 'Elixir.Logger.WatcherSupervisor' had child {'Elixir.Logger.WatcherSupervisor',
    {'Elixir.Logger','Elixir.Logger.Backends.Console'}} started with 'Elixir.Logger.Watcher':start_link({'Elixir.Logger','Elixir.Logger.Backends.Console',console}) at <0.175.0> exit with reason {'EXIT',{#{'__exception__' => true,'__struct__' => 'Elixir.RuntimeError',message => <<"no device registered with the name :user">>},[{'Elixir.Logger.Backends.Console',async_io,2,[{file,"lib/logger/backends/console.ex"},{line,160}]},{'Elixir.Logger.Backends.Console',log_event,5,[{file,"lib/logger/backends/console.ex"},{line,145}]},{'Elixir.Logger.Backends.Console',handle_event,2,[{file,"lib/logger/backends/console.ex"},{line,49}]},{gen_event,server_update,4,[{file,"gen_event.erl"},{line,577}]},...]}} in context child_terminated
2019-01-19 14:18:45.606 [error] <0.195.0> Lager event handler lager_console_backend exited with reason {'EXIT',{badarg,[{io,put_chars,[user,unicode,[["14",58,"18",58,"45",46,"348"]," ",[],"[","error","] ",[83,117,112,101,114,118,105,115,111,114,32,"{<0.60.0>,user_sup}",32,104,97,100,32,99,104,105,108,100,32,"at module user_sup at <0.61.0>",32,101,120,105,116,32,119,105,116,104,32,114,101,97,115,111,110,32,"einval",32,105,110,32,99,111,110,116,101,120,116,32,"child_terminated"],"\r\n"]],[]},{lager_console_backend,handle_event,2,[{file,"f:/fajne rzeczy/PT-LaboratoryMonitoring/controllstation/dep..."},...]},...]}}
2019-01-19 14:18:47.344 [error] <0.190.0>@lager_console_backend:handle_event:179 gen_event lager_console_backend installed in lager_event terminated with reason: bad argument in call to io:put_chars(user, unicode, [["14",58,"18",58,"46",46,"006"]," ",[],"[","warning","] ",[108,97,103,101,114,95,101,114,114,111,...],...]) in lager_console_backend:handle_event/2 line 179
2019-01-19 14:18:47.432 [error] <0.195.0> Lager event handler lager_console_backend exited with reason {'EXIT',{badarg,[{io,put_chars,[user,unicode,[["14",58,"18",58,"46",46,"006"]," ",[],"[","warning","] ",[108,97,103,101,114,95,101,114,114,111,114,95,108,111,103,103,101,114,95,104,32,100,114,111,112,112,101,100,32,"2",32,109,101,115,115,97,103,101,115,32,105,110,32,116,104,101,32,108,97,115,116,32,115,101,99,111,110,100,32,116,104,97,116,32,101,120,99,101,101,100,101,100,32,116,104,101,32,108,105,109,105,116,32,111,102,32,"50",32,109,101,115,115,97,103,101,115,47,115,101,99],"\r\n"]],[]},{lager_console_backend,...},...]}}
